<sdf version='1.12'>
  <world name='empty'>
    <physics name='1ms' type='ignored'>
      <max_step_size>0.001</max_step_size>
      <real_time_factor>1</real_time_factor>
      <real_time_update_rate>1000</real_time_update_rate>
    </physics>
    <plugin name='gz::sim::systems::Physics' filename='gz-sim-physics-system'/>
    <plugin name='gz::sim::systems::UserCommands' filename='gz-sim-user-commands-system'/>
    <plugin name='gz::sim::systems::SceneBroadcaster' filename='gz-sim-scene-broadcaster-system'/>
    <plugin name='gz::sim::systems::Sensors' filename='gz-sim-sensors-system'>
      <render_engine>ogre2</render_engine>
    </plugin>
    <plugin name='gz::sim::systems::Contact' filename='gz-sim-contact-system'/>
    <gravity>0 0 -9.8000000000000007</gravity>
    <magnetic_field>5.5644999999999998e-06 2.2875799999999999e-05 -4.2388400000000002e-05</magnetic_field>
    <atmosphere type='adiabatic'/>
    <scene>
      <ambient>0.400000006 0.400000006 0.400000006 1</ambient>
      <background>0.699999988 0.699999988 0.699999988 1</background>
      <shadows>true</shadows>
    </scene>
    <model name='ground_plane'>
      <static>true</static>
      <link name='link'>
        <collision name='collision'>
          <geometry>
            <plane>
              <normal>0 0 1</normal>
              <size>100 100</size>
            </plane>
          </geometry>
          <surface>
            <friction>
              <ode/>
            </friction>
            <bounce/>
            <contact/>
          </surface>
        </collision>
        <visual name='visual'>
          <geometry>
            <plane>
              <normal>0 0 1</normal>
              <size>100 100</size>
            </plane>
          </geometry>
          <material>
            <ambient>0.800000012 0.800000012 0.800000012 1</ambient>
            <diffuse>0.800000012 0.800000012 0.800000012 1</diffuse>
            <specular>0.800000012 0.800000012 0.800000012 1</specular>
          </material>
        </visual>
        <pose>0 0 0 0 0 0</pose>
        <inertial>
          <pose>0 0 0 0 0 0</pose>
          <mass>1</mass>
          <inertia>
            <ixx>1</ixx>
            <ixy>0</ixy>
            <ixz>0</ixz>
            <iyy>1</iyy>
            <iyz>0</iyz>
            <izz>1</izz>
          </inertia>
        </inertial>
        <enable_wind>false</enable_wind>
      </link>
      <pose>0 0 0 0 0 0</pose>
      <self_collide>false</self_collide>
    </model>
    <model name='diffdrive_bot'>
      <link name='base_link'>
        <inertial>
          <pose>0.065000000000000002 0 0.0625 0 0 0</pose>
          <mass>0.59999999999999998</mass>
          <inertia>
            <ixx>0.0052562499999999988</ixx>
            <ixy>0</ixy>
            <ixz>0.00056250000000000007</ixz>
            <iyy>0.0059312499999999964</iyy>
            <iyz>0</iyz>
            <izz>0.0082749999999999976</izz>
          </inertia>
        </inertial>
        <collision name='base_link_fixed_joint_lump__chassis_collision'>
          <pose>0.049999999999999989 0 0.074999999999999997 0 0 0</pose>
          <geometry>
            <box>
              <size>0.29999999999999999 0.29999999999999999 0.14999999999999999</size>
            </box>
          </geometry>
          <surface>
            <friction>
              <ode/>
            </friction>
            <bounce/>
            <contact/>
          </surface>
        </collision>
        <collision name='base_link_fixed_joint_lump__caster_wheel_collision_1'>
          <pose>0.14000000000000001 0 0 0 0 0</pose>
          <geometry>
            <sphere>
              <radius>0.050000000000000003</radius>
            </sphere>
          </geometry>
          <surface>
            <contact>
              <ode/>
            </contact>
            <friction>
              <ode>
                <mu>0.001</mu>
                <mu2>0.001</mu2>
              </ode>
            </friction>
            <bounce/>
          </surface>
        </collision>
        <visual name='base_link_fixed_joint_lump__chassis_visual'>
          <pose>0.049999999999999989 0 0.074999999999999997 0 0 0</pose>
          <geometry>
            <box>
              <size>0.29999999999999999 0.29999999999999999 0.14999999999999999</size>
            </box>
          </geometry>
          <material>
            <diffuse>1 1 1 1</diffuse>
            <ambient>1 1 1 1</ambient>
          </material>
        </visual>
        <visual name='base_link_fixed_joint_lump__caster_wheel_visual_1'>
          <pose>0.14000000000000001 0 0 0 0 0</pose>
          <geometry>
            <sphere>
              <radius>0.050000000000000003</radius>
            </sphere>
          </geometry>
          <material>
            <diffuse>0 0 0 1</diffuse>
            <ambient>0 0 0 1</ambient>
          </material>
        </visual>
        <pose>0 0 0 0 0 0</pose>
        <enable_wind>false</enable_wind>
      </link>
      <joint name='left_wheel_joint' type='revolute'>
        <pose>0 0 0 0 0 0</pose>
        <parent>base_link</parent>
        <child>left_wheel</child>
        <axis>
          <xyz>0 0 1</xyz>
          <limit>
            <lower>-inf</lower>
            <upper>inf</upper>
            <effort>inf</effort>
            <velocity>inf</velocity>
            <stiffness>100000000</stiffness>
            <dissipation>1</dissipation>
          </limit>
          <dynamics>
            <spring_reference>0</spring_reference>
            <spring_stiffness>0</spring_stiffness>
            <damping>0</damping>
            <friction>0</friction>
          </dynamics>
        </axis>
      </joint>
      <link name='left_wheel'>
        <pose>0 0.17499999999999999 0 1.5707963267948957 -0.78096946816663471 -3.1415926535897927</pose>
        <inertial>
          <pose>0 0 0 0 0 0</pose>
          <mass>0.10000000000000001</mass>
          <inertia>
            <ixx>7.5833333333333352e-05</ixx>
            <ixy>0</ixy>
            <ixz>0</ixz>
            <iyy>7.5833333333333352e-05</iyy>
            <iyz>0</iyz>
            <izz>0.000125</izz>
          </inertia>
        </inertial>
        <collision name='left_wheel_collision'>
          <pose>0 0 0 0 0 0</pose>
          <geometry>
            <cylinder>
              <length>0.040000000000000001</length>
              <radius>0.050000000000000003</radius>
            </cylinder>
          </geometry>
          <surface>
            <friction>
              <ode/>
            </friction>
            <bounce/>
            <contact/>
          </surface>
        </collision>
        <visual name='left_wheel_visual'>
          <pose>0 0 0 0 0 0</pose>
          <geometry>
            <cylinder>
              <length>0.040000000000000001</length>
              <radius>0.050000000000000003</radius>
            </cylinder>
          </geometry>
          <material>
            <diffuse>0.25 0.25 1 1</diffuse>
            <ambient>0.25 0.25 1 1</ambient>
          </material>
        </visual>
        <enable_wind>false</enable_wind>
      </link>
      <joint name='right_wheel_joint' type='revolute'>
        <pose>0 0 0 0 0 0</pose>
        <parent>base_link</parent>
        <child>right_wheel</child>
        <axis>
          <xyz>0 0 -1</xyz>
          <limit>
            <lower>-inf</lower>
            <upper>inf</upper>
            <effort>inf</effort>
            <velocity>inf</velocity>
            <stiffness>100000000</stiffness>
            <dissipation>1</dissipation>
          </limit>
          <dynamics>
            <spring_reference>0</spring_reference>
            <spring_stiffness>0</spring_stiffness>
            <damping>0</damping>
            <friction>0</friction>
          </dynamics>
        </axis>
      </joint>
      <link name='right_wheel'>
        <pose>0 -0.17499999999999988 -6.9388939039072284e-18 1.5707963267948941 1.2038208920960716 -2.1660237899497947e-15</pose>
        <inertial>
          <pose>0 0 0 0 0 0</pose>
          <mass>0.10000000000000001</mass>
          <inertia>
            <ixx>7.5833333333333352e-05</ixx>
            <ixy>0</ixy>
            <ixz>0</ixz>
            <iyy>7.5833333333333352e-05</iyy>
            <iyz>0</iyz>
            <izz>0.000125</izz>
          </inertia>
        </inertial>
        <collision name='right_wheel_collision'>
          <pose>0 0 0 0 0 0</pose>
          <geometry>
            <cylinder>
              <length>0.040000000000000001</length>
              <radius>0.050000000000000003</radius>
            </cylinder>
          </geometry>
          <surface>
            <friction>
              <ode/>
            </friction>
            <bounce/>
            <contact/>
          </surface>
        </collision>
        <visual name='right_wheel_visual'>
          <pose>0 0 0 0 0 0</pose>
          <geometry>
            <cylinder>
              <length>0.040000000000000001</length>
              <radius>0.050000000000000003</radius>
            </cylinder>
          </geometry>
          <material>
            <diffuse>0.25 0.25 1 1</diffuse>
            <ambient>0.25 0.25 1 1</ambient>
          </material>
        </visual>
        <enable_wind>false</enable_wind>
      </link>
      <plugin name='gz::sim::systems::DiffDrive' filename='gz-sim-diff-drive-system'>
        <left_joint>left_wheel_joint</left_joint>
        <right_joint>right_wheel_joint</right_joint>
        <wheel_separation>0.35</wheel_separation>
        <wheel_radius>0.05</wheel_radius>
        <max_linear_acceleration>0.033</max_linear_acceleration>
        <topic>cmd_vel</topic>
        <frame_id>odom</frame_id>
        <child_frame_id>base_link</child_frame_id>
        <odom_topic>odom</odom_topic>
        <odom_publisher_frequency>30</odom_publisher_frequency>
        <tf_topic>/tf</tf_topic>
      </plugin>
      <plugin name='gz::sim::systems::JointStatePublisher' filename='gz-sim-joint-state-publisher-system'>
        <topic>joint_states</topic>
        <joint_name>left_wheel_joint</joint_name>
        <joint_name>right_wheel_joint</joint_name>
      </plugin>
      <frame name='caster_wheel_joint' attached_to='chassis'>
        <pose>0.23999999999999999 0 0 0 0 0</pose>
      </frame>
      <frame name='caster_wheel' attached_to='caster_wheel_joint'>
        <pose>0 0 0 0 0 0</pose>
      </frame>
      <frame name='chassis_joint' attached_to='base_link'>
        <pose>-0.10000000000000001 0 0 0 0 0</pose>
      </frame>
      <frame name='chassis' attached_to='chassis_joint'>
        <pose>0 0 0 0 0 0</pose>
      </frame>
      <pose>0.34571860863972309 0.37525661241040331 0.049999994838537232 9.7499859750950084e-10 1.0682058427710731e-08 -2.7243430809544265</pose>
      <static>false</static>
      <self_collide>false</self_collide>
    </model>
    <model name='Construction Cone'>
      <link name='link'>
        <collision name='collision'>
          <geometry>
            <mesh>
              <scale>10 10 10</scale>
              <uri>https://fuel.gazebosim.org/1.0/openrobotics/models/construction cone/3/files/meshes/construction_cone.dae</uri>
            </mesh>
          </geometry>
        </collision>
        <visual name='visual'>
          <geometry>
            <mesh>
              <scale>10 10 10</scale>
              <uri>https://fuel.gazebosim.org/1.0/openrobotics/models/construction cone/3/files/meshes/construction_cone.dae</uri>
            </mesh>
          </geometry>
        </visual>
        <pose>0 0 0 0 0 0</pose>
        <inertial>
          <pose>0 0 0 0 0 0</pose>
          <mass>1</mass>
          <inertia>
            <ixx>1</ixx>
            <ixy>0</ixy>
            <ixz>0</ixz>
            <iyy>1</iyy>
            <iyz>0</iyz>
            <izz>1</izz>
          </inertia>
        </inertial>
        <enable_wind>false</enable_wind>
      </link>
      <pose>1.1418999433517456 -0.75494533777236938 -5.2719347777910114e-11 -5.8926380282814411e-20 -8.6980086710255251e-20 -4.2732884819235222e-30</pose>
      <static>false</static>
      <self_collide>false</self_collide>
    </model>
    <model name='Construction Cone_0'>
      <link name='link'>
        <collision name='collision'>
          <geometry>
            <mesh>
              <scale>10 10 10</scale>
              <uri>https://fuel.gazebosim.org/1.0/openrobotics/models/construction cone/3/files/meshes/construction_cone.dae</uri>
            </mesh>
          </geometry>
        </collision>
        <visual name='visual'>
          <geometry>
            <mesh>
              <scale>10 10 10</scale>
              <uri>https://fuel.gazebosim.org/1.0/openrobotics/models/construction cone/3/files/meshes/construction_cone.dae</uri>
            </mesh>
          </geometry>
        </visual>
        <pose>0 0 0 0 0 0</pose>
        <inertial>
          <pose>0 0 0 0 0 0</pose>
          <mass>1</mass>
          <inertia>
            <ixx>1</ixx>
            <ixy>0</ixy>
            <ixz>0</ixz>
            <iyy>1</iyy>
            <iyz>0</iyz>
            <izz>1</izz>
          </inertia>
        </inertial>
        <enable_wind>false</enable_wind>
      </link>
      <pose>-0.86960372361683502 -1.0294852069212528 -1.3379350696784975e-11 2.7647155398380365e-21 2.2226144535952842e-21 3.0724483594617546e-42</pose>
      <static>false</static>
      <self_collide>false</self_collide>
    </model>
    <model name='Construction Cone_1'>
      <link name='link'>
        <collision name='collision'>
          <geometry>
            <mesh>
              <scale>10 10 10</scale>
              <uri>https://fuel.gazebosim.org/1.0/openrobotics/models/construction cone/3/files/meshes/construction_cone.dae</uri>
            </mesh>
          </geometry>
        </collision>
        <visual name='visual'>
          <geometry>
            <mesh>
              <scale>10 10 10</scale>
              <uri>https://fuel.gazebosim.org/1.0/openrobotics/models/construction cone/3/files/meshes/construction_cone.dae</uri>
            </mesh>
          </geometry>
        </visual>
        <pose>0 0 0 0 0 0</pose>
        <inertial>
          <pose>0 0 0 0 0 0</pose>
          <mass>1</mass>
          <inertia>
            <ixx>1</ixx>
            <ixy>0</ixy>
            <ixz>0</ixz>
            <iyy>1</iyy>
            <iyz>0</iyz>
            <izz>1</izz>
          </inertia>
        </inertial>
        <enable_wind>false</enable_wind>
      </link>
      <pose>-0.46031632254389709 0.98428266679747844 -1.3379350696784975e-11 8.6736173798840357e-22 -1.8973538018496328e-22 -8.2284604557560124e-44</pose>
      <static>false</static>
      <self_collide>false</self_collide>
    </model>
    <model name='Construction Cone_2'>
      <link name='link'>
        <collision name='collision'>
          <geometry>
            <mesh>
              <scale>10 10 10</scale>
              <uri>https://fuel.gazebosim.org/1.0/openrobotics/models/construction cone/3/files/meshes/construction_cone.dae</uri>
            </mesh>
          </geometry>
        </collision>
        <visual name='visual'>
          <geometry>
            <mesh>
              <scale>10 10 10</scale>
              <uri>https://fuel.gazebosim.org/1.0/openrobotics/models/construction cone/3/files/meshes/construction_cone.dae</uri>
            </mesh>
          </geometry>
        </visual>
        <pose>0 0 0 0 0 0</pose>
        <inertial>
          <pose>0 0 0 0 0 0</pose>
          <mass>1</mass>
          <inertia>
            <ixx>1</ixx>
            <ixy>0</ixy>
            <ixz>0</ixz>
            <iyy>1</iyy>
            <iyz>0</iyz>
            <izz>1</izz>
          </inertia>
        </inertial>
        <enable_wind>false</enable_wind>
      </link>
      <pose>1.5882799625396729 0.97143232822418213 -2.662460042886207e-11 -1.1969590910924658e-19 -5.2909066597894241e-20 -2.4536353397179787e-29</pose>
      <static>false</static>
      <self_collide>false</self_collide>
    </model>
    <light name='sun' type='directional'>
      <pose>0 0 10 0 0 0</pose>
      <cast_shadows>true</cast_shadows>
      <intensity>1</intensity>
      <direction>-0.5 0.10000000000000001 -0.90000000000000002</direction>
      <diffuse>0.800000012 0.800000012 0.800000012 1</diffuse>
      <specular>0.200000003 0.200000003 0.200000003 1</specular>
      <attenuation>
        <range>1000</range>
        <linear>0.01</linear>
        <constant>0.90000000000000002</constant>
        <quadratic>0.001</quadratic>
      </attenuation>
      <spot>
        <inner_angle>0</inner_angle>
        <outer_angle>0</outer_angle>
        <falloff>0</falloff>
      </spot>
    </light>
  </world>
</sdf>
